2024-12-25 11:12:10,727 | ERROR    | django.request       | log:248 | Internal Server Error: /api/resumes/upload/
2024-12-25 11:12:10,728 | ERROR    | django.server        | basehttp:213 | "POST /api/resumes/upload/ HTTP/1.1" 500 168
2024-12-25 11:43:44,741 | ERROR    | django.request       | log:248 | Internal Server Error: /api/resumes/upload/
2024-12-25 11:43:44,773 | ERROR    | django.server        | basehttp:213 | "POST /api/resumes/upload/ HTTP/1.1" 500 168
2024-12-27 10:26:12,857 | ERROR    | django.security.DisallowedHost | exception:124 | Invalid HTTP_HOST header: '127.0.0.1:8000'. You may need to add '127.0.0.1' to ALLOWED_HOSTS.
Traceback (most recent call last):
  File "D:\Projects\Job_Search_Platfrom\Backend\venv\Lib\site-packages\django\core\handlers\exception.py", line 55, in inner
    response = get_response(request)
               ^^^^^^^^^^^^^^^^^^^^^
  File "D:\Projects\Job_Search_Platfrom\Backend\venv\Lib\site-packages\django\utils\deprecation.py", line 128, in __call__
    response = self.process_request(request)
               ^^^^^^^^^^^^^^^^^^^^^^^^^^^^^
  File "D:\Projects\Job_Search_Platfrom\Backend\venv\Lib\site-packages\django\middleware\common.py", line 48, in process_request
    host = request.get_host()
           ^^^^^^^^^^^^^^^^^^
  File "D:\Projects\Job_Search_Platfrom\Backend\venv\Lib\site-packages\django\http\request.py", line 151, in get_host
    raise DisallowedHost(msg)
django.core.exceptions.DisallowedHost: Invalid HTTP_HOST header: '127.0.0.1:8000'. You may need to add '127.0.0.1' to ALLOWED_HOSTS.
2024-12-27 10:27:15,765 | ERROR    | django.request       | log:248 | Internal Server Error: /api/resumes/1
Traceback (most recent call last):
  File "D:\Projects\Job_Search_Platfrom\Backend\venv\Lib\site-packages\django\core\handlers\exception.py", line 55, in inner
    response = get_response(request)
               ^^^^^^^^^^^^^^^^^^^^^
  File "D:\Projects\Job_Search_Platfrom\Backend\venv\Lib\site-packages\django\utils\deprecation.py", line 131, in __call__
    response = self.process_response(request, response)
               ^^^^^^^^^^^^^^^^^^^^^^^^^^^^^^^^^^^^^^^^
  File "D:\Projects\Job_Search_Platfrom\Backend\venv\Lib\site-packages\django\middleware\common.py", line 108, in process_response
    return self.response_redirect_class(self.get_full_path_with_slash(request))
                                        ^^^^^^^^^^^^^^^^^^^^^^^^^^^^^^^^^^^^^^
  File "D:\Projects\Job_Search_Platfrom\Backend\venv\Lib\site-packages\django\middleware\common.py", line 87, in get_full_path_with_slash
    raise RuntimeError(
RuntimeError: You called this URL via POST, but the URL doesn't end in a slash and you have APPEND_SLASH set. Django can't redirect to the slash URL while maintaining POST data. Change your form to point to localhost:8000/api/resumes/1/ (note the trailing slash), or set APPEND_SLASH=False in your Django settings.
2024-12-27 10:27:15,806 | ERROR    | django.server        | basehttp:213 | "POST /api/resumes/1 HTTP/1.1" 500 75271
2024-12-27 10:29:15,297 | ERROR    | django.request       | log:248 | Internal Server Error: /api/users/login
Traceback (most recent call last):
  File "D:\Projects\Job_Search_Platfrom\Backend\venv\Lib\site-packages\django\core\handlers\exception.py", line 55, in inner
    response = get_response(request)
               ^^^^^^^^^^^^^^^^^^^^^
  File "D:\Projects\Job_Search_Platfrom\Backend\venv\Lib\site-packages\django\utils\deprecation.py", line 131, in __call__
    response = self.process_response(request, response)
               ^^^^^^^^^^^^^^^^^^^^^^^^^^^^^^^^^^^^^^^^
  File "D:\Projects\Job_Search_Platfrom\Backend\venv\Lib\site-packages\django\middleware\common.py", line 108, in process_response
    return self.response_redirect_class(self.get_full_path_with_slash(request))
                                        ^^^^^^^^^^^^^^^^^^^^^^^^^^^^^^^^^^^^^^
  File "D:\Projects\Job_Search_Platfrom\Backend\venv\Lib\site-packages\django\middleware\common.py", line 87, in get_full_path_with_slash
    raise RuntimeError(
RuntimeError: You called this URL via POST, but the URL doesn't end in a slash and you have APPEND_SLASH set. Django can't redirect to the slash URL while maintaining POST data. Change your form to point to localhost:8000/api/users/login/ (note the trailing slash), or set APPEND_SLASH=False in your Django settings.
2024-12-27 10:29:15,300 | ERROR    | django.server        | basehttp:213 | "POST /api/users/login HTTP/1.1" 500 75303
2024-12-27 11:06:15,972 | ERROR    | django.request       | log:248 | Internal Server Error: /api/resumes/upload/
2024-12-27 11:06:15,983 | ERROR    | django.server        | basehttp:213 | "POST /api/resumes/upload/ HTTP/1.1" 500 212
2024-12-27 11:14:13,240 | ERROR    | django.request       | log:248 | Internal Server Error: /api/resumes/1/
Traceback (most recent call last):
  File "D:\Projects\Job_Search_Platfrom\Backend\project_root\apps\resumes\views.py", line 95, in get_resume_details
    resume = Resume.objects.get(id=resume_id, user=request.user)
             ^^^^^^^^^^^^^^^^^^^^^^^^^^^^^^^^^^^^^^^^^^^^^^^^^^^
  File "D:\Projects\Job_Search_Platfrom\Backend\venv\Lib\site-packages\django\db\models\manager.py", line 87, in manager_method
    return getattr(self.get_queryset(), name)(*args, **kwargs)
           ^^^^^^^^^^^^^^^^^^^^^^^^^^^^^^^^^^^^^^^^^^^^^^^^^^^
  File "D:\Projects\Job_Search_Platfrom\Backend\venv\Lib\site-packages\django\db\models\query.py", line 649, in get
    raise self.model.DoesNotExist(
apps.resumes.models.Resume.DoesNotExist: Resume matching query does not exist.

During handling of the above exception, another exception occurred:

Traceback (most recent call last):
  File "D:\Projects\Job_Search_Platfrom\Backend\venv\Lib\site-packages\django\core\handlers\exception.py", line 55, in inner
    response = get_response(request)
               ^^^^^^^^^^^^^^^^^^^^^
  File "D:\Projects\Job_Search_Platfrom\Backend\venv\Lib\site-packages\django\core\handlers\base.py", line 197, in _get_response
    response = wrapped_callback(request, *callback_args, **callback_kwargs)
               ^^^^^^^^^^^^^^^^^^^^^^^^^^^^^^^^^^^^^^^^^^^^^^^^^^^^^^^^^^^^
  File "D:\Projects\Job_Search_Platfrom\Backend\venv\Lib\site-packages\django\views\decorators\csrf.py", line 65, in _view_wrapper
    return view_func(request, *args, **kwargs)
           ^^^^^^^^^^^^^^^^^^^^^^^^^^^^^^^^^^^
  File "D:\Projects\Job_Search_Platfrom\Backend\venv\Lib\site-packages\django\views\generic\base.py", line 104, in view
    return self.dispatch(request, *args, **kwargs)
           ^^^^^^^^^^^^^^^^^^^^^^^^^^^^^^^^^^^^^^^
  File "D:\Projects\Job_Search_Platfrom\Backend\venv\Lib\site-packages\rest_framework\views.py", line 509, in dispatch
    response = self.handle_exception(exc)
               ^^^^^^^^^^^^^^^^^^^^^^^^^^
  File "D:\Projects\Job_Search_Platfrom\Backend\venv\Lib\site-packages\rest_framework\views.py", line 469, in handle_exception
    self.raise_uncaught_exception(exc)
  File "D:\Projects\Job_Search_Platfrom\Backend\venv\Lib\site-packages\rest_framework\views.py", line 480, in raise_uncaught_exception
    raise exc
  File "D:\Projects\Job_Search_Platfrom\Backend\venv\Lib\site-packages\rest_framework\views.py", line 506, in dispatch
    response = handler(request, *args, **kwargs)
               ^^^^^^^^^^^^^^^^^^^^^^^^^^^^^^^^^
  File "D:\Projects\Job_Search_Platfrom\Backend\venv\Lib\site-packages\rest_framework\decorators.py", line 50, in handler
    return func(*args, **kwargs)
           ^^^^^^^^^^^^^^^^^^^^^
  File "D:\Projects\Job_Search_Platfrom\Backend\project_root\apps\resumes\views.py", line 100, in get_resume_details
    return Response({"error": "Resume not found"}, status=status.HTTP_404_NOT_FOUND)
                                                          ^^^^^^
NameError: name 'status' is not defined
2024-12-27 11:14:13,246 | ERROR    | django.server        | basehttp:213 | "GET /api/resumes/1/ HTTP/1.1" 500 118394
2024-12-27 11:14:13,404 | ERROR    | django.request       | log:248 | Internal Server Error: /api/resumes/1/
Traceback (most recent call last):
  File "D:\Projects\Job_Search_Platfrom\Backend\project_root\apps\resumes\views.py", line 95, in get_resume_details
    resume = Resume.objects.get(id=resume_id, user=request.user)
             ^^^^^^^^^^^^^^^^^^^^^^^^^^^^^^^^^^^^^^^^^^^^^^^^^^^
  File "D:\Projects\Job_Search_Platfrom\Backend\venv\Lib\site-packages\django\db\models\manager.py", line 87, in manager_method
    return getattr(self.get_queryset(), name)(*args, **kwargs)
           ^^^^^^^^^^^^^^^^^^^^^^^^^^^^^^^^^^^^^^^^^^^^^^^^^^^
  File "D:\Projects\Job_Search_Platfrom\Backend\venv\Lib\site-packages\django\db\models\query.py", line 649, in get
    raise self.model.DoesNotExist(
apps.resumes.models.Resume.DoesNotExist: Resume matching query does not exist.

During handling of the above exception, another exception occurred:

Traceback (most recent call last):
  File "D:\Projects\Job_Search_Platfrom\Backend\venv\Lib\site-packages\django\core\handlers\exception.py", line 55, in inner
    response = get_response(request)
               ^^^^^^^^^^^^^^^^^^^^^
  File "D:\Projects\Job_Search_Platfrom\Backend\venv\Lib\site-packages\django\core\handlers\base.py", line 197, in _get_response
    response = wrapped_callback(request, *callback_args, **callback_kwargs)
               ^^^^^^^^^^^^^^^^^^^^^^^^^^^^^^^^^^^^^^^^^^^^^^^^^^^^^^^^^^^^
  File "D:\Projects\Job_Search_Platfrom\Backend\venv\Lib\site-packages\django\views\decorators\csrf.py", line 65, in _view_wrapper
    return view_func(request, *args, **kwargs)
           ^^^^^^^^^^^^^^^^^^^^^^^^^^^^^^^^^^^
  File "D:\Projects\Job_Search_Platfrom\Backend\venv\Lib\site-packages\django\views\generic\base.py", line 104, in view
    return self.dispatch(request, *args, **kwargs)
           ^^^^^^^^^^^^^^^^^^^^^^^^^^^^^^^^^^^^^^^
  File "D:\Projects\Job_Search_Platfrom\Backend\venv\Lib\site-packages\rest_framework\views.py", line 509, in dispatch
    response = self.handle_exception(exc)
               ^^^^^^^^^^^^^^^^^^^^^^^^^^
  File "D:\Projects\Job_Search_Platfrom\Backend\venv\Lib\site-packages\rest_framework\views.py", line 469, in handle_exception
    self.raise_uncaught_exception(exc)
  File "D:\Projects\Job_Search_Platfrom\Backend\venv\Lib\site-packages\rest_framework\views.py", line 480, in raise_uncaught_exception
    raise exc
  File "D:\Projects\Job_Search_Platfrom\Backend\venv\Lib\site-packages\rest_framework\views.py", line 506, in dispatch
    response = handler(request, *args, **kwargs)
               ^^^^^^^^^^^^^^^^^^^^^^^^^^^^^^^^^
  File "D:\Projects\Job_Search_Platfrom\Backend\venv\Lib\site-packages\rest_framework\decorators.py", line 50, in handler
    return func(*args, **kwargs)
           ^^^^^^^^^^^^^^^^^^^^^
  File "D:\Projects\Job_Search_Platfrom\Backend\project_root\apps\resumes\views.py", line 100, in get_resume_details
    return Response({"error": "Resume not found"}, status=status.HTTP_404_NOT_FOUND)
                                                          ^^^^^^
NameError: name 'status' is not defined
2024-12-27 11:14:13,411 | ERROR    | django.server        | basehttp:213 | "GET /api/resumes/1/ HTTP/1.1" 500 118394
